Script started on 2018-12-05 22:03:40+0000
pjd@vm-101:~/2018-fall/cs5600-f18/hw3/repos/team-1-hw3$ python ../../tests-q1.py
Test 1, getattr:
   /
   /file.A
   /dir1
   /dir1/file.2
   /dir1/file.0
   /dir1/file.270
   /file.7
.Test 2, readdir:
  /
  /dir1/
.Test 3, full read:
   /file.A
   file.7
   dir1/file.0
   dir1/file.2
   /dir1/file.270
.Test 4, small reads:
.Test 5, getattr failure cases:
   /not-a-file : ENOENT
   /dir1/not-a-file : ENOENT
   /not-a-dir/file.0 : ENOENT
   /file.A/file.0 : ENOTDIR
   /dir1/file.0/testing : ENOTDIR
   /dir1/thisisaverylongnamelongerthan27chars : ENOENT
.Test 6, read failure cases:
   /not-a-file : ENOENT
   /dir1 : EISDIR
   /not-a-dir/file.0 : ENOENT
   /file.A/file.0 : ENOTDIR
.Test 7, readdir failure cases:
   /not-a-dir : ENOENT
   /file.A : ENOTDIR
   /not-a-dir/file.0 : ENOENT
   /dir1/file.0 : ENOTDIR
.Test 8, vfsstat
F
======================================================================
FAIL: test_8_stat (__main__.tests)
----------------------------------------------------------------------
Traceback (most recent call last):
  File "../../test-q1.py", line 141, in test_8_stat
    self.assertEquals(stat.f_blocks, 1024, msg='f_blocks')
AssertionError: f_blocks

----------------------------------------------------------------------
Ran 8 tests in 0.067s

FAILED (failures=1)
pjd@vm-101:~/2018-fall/cs5600-f18/hw3/repos/team-1-hw3$ diff hw3test.py ../../hw3test.py
pjd@vm-101:~/2018-fall/cs5600-f18/hw3/repos/team-1-hw3$ python ../../test-q1.py verbose test_8_stat
Traceback (most recent call last):
  File "../../test-q1.py", line 146, in <module>
    unittest.main()
  File "/usr/lib/python2.7/unittest/main.py", line 94, in __init__
    self.parseArgs(argv)
  File "/usr/lib/python2.7/unittest/main.py", line 149, in parseArgs
    self.createTests()
  File "/usr/lib/python2.7/unittest/main.py", line 158, in createTests
    self.module)
  File "/usr/lib/python2.7/unittest/loader.py", line 130, in loadTestsFromNames
    suites = [self.loadTestsFromName(name, module) for name in names]
  File "/usr/lib/python2.7/unittest/loader.py", line 100, in loadTestsFromName
    parent, obj = obj, getattr(obj, part)
AttributeError: 'module' object has no attribute 'test_8_stat'
pjd@vm-101:~/2018-fall/cs5600-f18/hw3/repos/team-1-hw3$ python ../../test-q1.py verbose test_8_stattest_8_statetest_8_statstest_8_stattest_8_statstest_8_stat.test_8_stat pjd@vm-101:~/2018-fall/cs5600-f18/hw3/repos/team-1-hw3$ 

Test 8, vfsstat
statfs() = 0 (size=1024 blocks=1017 bfree=731 namemax=27)
F
======================================================================
FAIL: test_8_stat (__main__.tests)
----------------------------------------------------------------------
Traceback (most recent call last):
  File "../../test-q1.py", line 141, in test_8_stat
    self.assertEquals(stat.f_blocks, 1024, msg='f_blocks')
AssertionError: f_blocks

----------------------------------------------------------------------
Ran 1 test in 0.001s

FAILED (failures=1)
pjd@vm-101:~/2018-fall/cs5600-f18/hw3/repos/team-1-hw3$ exit

Script done on 2018-12-05 22:04:31+0000
